<?xml version="1.0" ?>
<robot xmlns:xacro="http://ros.org/wiki/xacro">

    <xacro:macro name="mh5_leg" params="side parent">

        <xacro:property name="short_side" value="${side[0]}"/>
        <xacro:if value="${short_side == 'l'}">
            <xacro:property name="factor" value = "1.0"/>
        </xacro:if>
        <xacro:if value="${short_side == 'r'}">
            <xacro:property name="factor" value = "-1.0"/>
        </xacro:if>

        <link name="${side}_hipy_servo">
            <visual>
                <origin rpy="0 ${pi} ${pi/2}" xyz="0 0 0"/>
                <geometry>
                    <mesh filename="package://mh5_description/meshes/xl430_no_idle.stl"/>
                </geometry>
                <xacro:material_black/>
            </visual>
        </link>

        <joint name="${side}_hipy_fixed" type="fixed">
            <parent link="${parent}"/>
            <child link="${side}_hipy_servo"/>
            <origin xyz="-0.0105 ${factor*0.04575} -0.017" rpy="0 0 0"/>
        </joint>

        <link name="${side}_hip_frame">
            <visual>
                <origin rpy="0 0 ${factor*pi/2}" xyz="0 0 -0.045"/>
                <geometry>
                    <mesh filename="package://mh5_description/meshes/frame02.stl"/>
                </geometry>
                <material name="ivory"/>
            </visual>
        </link>

        <joint name="${short_side}_hip_y" type="revolute">
            <axis xyz="0 0 ${factor}"/>
            <parent link="${side}_hipy_servo"/>
            <child link="${side}_hip_frame"/>
            <origin xyz="0 0 0" rpy="0 0 0"/>
            <limit lower="-3.1416" upper="3.1416" effort="1000" velocity="100"/>
        </joint>

        <link name="${side}_hip_servo">
            <visual>
                <origin rpy="${pi/2} 0 0" xyz="0 0 -0.012"/>
                <geometry>
                    <mesh filename="package://mh5_description/meshes/2xl430_2_idles.stl"/>
                </geometry>
                <material name="black"/>
            </visual>
        </link>

        <joint name="${short_side}_hip_p" type="revolute">
            <axis xyz="0 -1 0"/>
            <parent link="${side}_hip_frame"/>
            <child link="${side}_hip_servo"/>
            <origin xyz="0 0 -0.045" rpy="0 0 0"/>
            <limit lower="-3.1416" upper="3.1416" effort="1000" velocity="100"/>
        </joint>

        <link name="${side}_thigh_frame">
            <visual>
                <origin rpy="0 0 ${pi/2}" xyz="0 0 0"/>
                <geometry>
                    <mesh filename="package://mh5_description/meshes/thigh.stl"/>
                </geometry>
                <material name="ivory"/>
            </visual>
        </link>

        <joint name="${short_side}_hip_r" type="revolute">
            <axis xyz="${factor} 0 0"/>
            <parent link="${side}_hip_servo"/>
            <child link="${side}_thigh_frame"/>
            <origin xyz="0 0 -0.024" rpy="0 0 0"/>
            <limit lower="-3.1416" upper="3.1416" effort="1000" velocity="100"/>
        </joint>

        <link name="${side}_knee_servo">
            <visual>
                <origin rpy="${pi/2} 0 0" xyz="0 0 0"/>
                <geometry>
                    <mesh filename="package://mh5_description/meshes/xl430_with_idle.stl"/>
                </geometry>
                <material name="black"/>
            </visual>
        </link>

        <joint name="${short_side}_kne_p" type="revolute">
            <axis xyz="0 1 0"/>
            <parent link="${side}_thigh_frame"/>
            <child link="${side}_knee_servo"/>
            <origin xyz="-0.0065 0 -0.049" rpy="0 0 0"/>
            <limit lower="-3.1416" upper="3.1416" effort="1000" velocity="100"/>
        </joint>

        <link name="${side}_calf_frame">
            <visual>
                <origin rpy="0 0 ${pi/2}" xyz="0 0 0"/>
                <geometry>
                    <mesh filename="package://mh5_description/meshes/calf.stl"/>
                </geometry>
                <material name="ivory"/>
            </visual>
        </link>

        <joint name="${side}_calf_fixed" type="fixed">
            <parent link="${side}_knee_servo"/>
            <child link="${side}_calf_frame"/>
            <origin xyz="0 0 -0.032" rpy="0 0 0"/>
        </joint>

        <link name="${side}_ankle_servo">
            <visual>
                <origin rpy="${pi/2} 0 0" xyz="0 0 -0.012"/>
                <geometry>
                    <mesh filename="package://mh5_description/meshes/2xl430_2_idles.stl"/>
                </geometry>
                <material name="black"/>
            </visual>
        </link>

        <joint name="${short_side}_ank_p" type="revolute">
            <axis xyz="0 -1 0"/>
            <parent link="${side}_calf_frame"/>
            <child link="${side}_ankle_servo"/>
            <origin xyz="0 0 -0.03325" rpy="0 0 0"/>
            <limit lower="-3.1416" upper="3.1416" effort="1000" velocity="100"/>
        </joint>

        <link name="${side}_foot">
            <visual>
                <origin rpy="0 0 ${pi/2}" xyz="0 0 0"/>
                <geometry>
                    <mesh filename="package://mh5_description/meshes/foot.stl"/>
                </geometry>
                <material name="ivory"/>
            </visual>
        </link>

        <joint name="${short_side}_ank_r" type="revolute">
            <axis xyz="${factor} 0 0"/>
            <parent link="${side}_ankle_servo"/>
            <child link="${side}_foot"/>
            <origin xyz="0 0 -0.024" rpy="0 0 0"/>
            <limit lower="-3.1416" upper="3.1416" effort="1000" velocity="100"/>
        </joint>

        <link name="${side}_hot_swap">
            <visual>
                <origin rpy="0 0 ${-factor*pi/2}" xyz="0 0 0"/>
                <geometry>
                    <mesh filename="package://mh5_description/meshes/hot_swap.stl"/>
                </geometry>
                <material name="ivory"/>
            </visual>
        </link>

        <joint name="${side}_hs_fixed" type="fixed">
            <parent link="${side}_foot"/>
            <child link="${side}_hot_swap"/>
            <origin xyz="-0.0335 0 -0.026" rpy="0 0 0"/>
        </joint>

        <link name="${side}_battery">
            <visual>
                <origin rpy="0 0 ${-pi/2}" xyz="0 0 0"/>
                <geometry>
                    <mesh filename="package://mh5_description/meshes/battery.stl"/>
                </geometry>
                <material name="blue">
                    <color rgba="0.2 0.2 0.9 1"/>
                </material>
            </visual>
        </link>

        <joint name="${side}_battery_fixed" type="fixed">
            <parent link="${side}_foot"/>
            <child link="${side}_battery"/>
            <origin xyz="0.009 0 -0.045" rpy="0 0 0"/>
        </joint>

    </xacro:macro>

</robot>