<?xml version="1.0" ?>
<robot xmlns:xacro="http://ros.org/wiki/xacro">

    <xacro:macro name="mh5_arm" params="side parent">

        <xacro:property name="short_side" value="${side[0]}"/>
        <xacro:if value="${short_side == 'l'}">
            <xacro:property name="factor" value = "1.0"/>
        </xacro:if>
        <xacro:if value="${short_side == 'r'}">
            <xacro:property name="factor" value = "-1.0"/>
        </xacro:if>

        <xacro:property name="effort" value="1.0"/>
        <xacro:property name="velocity" value="${2*pi}"/>

        <joint name="${side}_shoulder_fixed" type="fixed">
            <parent link="${parent}"/>
            <child link="${side}_shoulder_servo"/>
            <origin xyz="0 ${factor*0.0495} 0.11875" rpy="0 0 ${factor*pi/2}"/>
        </joint>

        <link name="${side}_shoulder_servo">
            <visual>
                <origin rpy="0 0 0" xyz="0 0 0"/>
                <geometry>
                    <mesh filename="package://mh5_description/meshes/XL430_no_idle_revC.stl"/>
                </geometry>
                <xacro:material_black/>
            </visual>
            <collision>
                <origin rpy="0 0 0" xyz="0 0 0"/>
                <geometry>
                    <mesh filename="package://mh5_description/meshes/XL430_no_idle_revC.stl"/>
                </geometry>
            </collision>
            <inertial>
                <mass value="0.057"/>
                <inertia
                    ixx="0.000013720"
                    iyy="0.000015234"
                    izz="0.000008769"
                    ixy="0.000000007"
                    ixz="-0.000000355"
                    iyz="0.000000006" />
            </inertial>
        </link>

        <joint name="${short_side}_sho_p" type="revolute">
            <axis xyz="0 0 ${factor}"/>
            <parent link="${side}_shoulder_servo"/>
            <child link="${side}_shoulder_frame"/>
            <origin xyz="0.019 0 0" rpy="0 -${pi/2} 0"/>
            <!-- <origin xyz="0 0 0.019" rpy="0 ${pi} ${pi/2 - factor*pi/2}"/> -->
            <limit lower="-${pi/2}" upper="${pi}" effort="${effort}" velocity="${velocity}"/>
        </joint>
        <xacro:insert_transmission name="${short_side}_sho_p"/>

        <link name="${side}_shoulder_frame">
            <visual>
                <origin rpy="0 0 0" xyz="0 0 0"/>
                <geometry>
                    <mesh filename="package://mh5_description/meshes/frame01_revC.stl"/>
                </geometry>
                <material name="ivory"/>
            </visual>
            <collision>
                <origin rpy="0 0 0" xyz="0 0 0"/>
                <geometry>
                    <mesh filename="package://mh5_description/meshes/frame01_revC.stl"/>
                </geometry>
            </collision>
            <inertial>
                <mass value="0.0083"/>
                <inertia
                    ixx="0.000003285"
                    iyy="0.000001666"
                    izz="0.000003578"
                    ixy="0.000000000"
                    ixz="-0.000000402"
                    iyz="0.000000000" />
            </inertial>
        </link>

        <joint name="${short_side}_sho_r" type="revolute">
            <axis xyz="${factor} 0 0"/>
            <parent link="${side}_shoulder_frame"/>
            <child link="${side}_arm_servo"/>
            <origin xyz="-0.024 0 -0.027" rpy="${-factor*pi/2} 0 ${-factor*pi/2}"/>
            <!-- <origin xyz="0 ${-factor*0.016} -0.027" rpy="0 ${pi/2} ${pi/2 - factor*pi/2}"/> -->
            <limit lower="0" upper="${pi}" effort="${effort}" velocity="${velocity}"/>
        </joint>
        <xacro:insert_transmission name="${short_side}_sho_r"/>

        <link name="${side}_arm_servo">
            <visual>
                <origin rpy="0 0 0" xyz="0 0 0"/>
                <geometry>
                    <mesh filename="package://mh5_description/meshes/XL430_idle_revC.stl"/>
                </geometry>
                <material name="black"/>
            </visual>
            <collision>
                <origin rpy="0 0 0" xyz="0 0 0"/>
                <geometry>
                    <mesh filename="package://mh5_description/meshes/XL430_idle_revC.stl"/>
                </geometry>
            </collision>
            <inertial>
                <mass value="0.057"/>
                <inertia
                    ixx="0.000013720"
                    iyy="0.000015234"
                    izz="0.000008769"
                    ixy="0.000000007"
                    ixz="-0.000000355"
                    iyz="0.000000006" />
            </inertial>
        </link>

        <joint name="${side}_arm_fixed" type="fixed">
            <parent link="${side}_arm_servo"/>
            <child link="${side}_arm_frame"/>
            <origin xyz="0 0 -0.03925" rpy="0 0 ${pi/2}"/>
        </joint>

        <link name="${side}_arm_frame">
            <visual>
                <origin rpy="0 0 0" xyz="0 0 0"/>
                <geometry>
                    <mesh filename="package://mh5_description/meshes/frame03_revC.stl"/>
                </geometry>
                <material name="ivory"/>
            </visual>
            <collision>
                <origin rpy="0 0 0" xyz="0 0 0"/>
                <geometry>
                    <mesh filename="package://mh5_description/meshes/frame03_revC.stl"/>
                </geometry>
            </collision>
            <inertial>
                <mass value="0.0028"/>
                <inertia
                    ixx="0.000000349"
                    iyy="0.000000241"
                    izz="0.000000567"
                    ixy="0"
                    ixz="0"
                    iyz="0" />
            </inertial>
        </link>

        <joint name="${short_side}_elb_y" type="revolute">
            <axis xyz="${factor} 0 0"/>
            <parent link="${side}_arm_frame"/>
            <child link="${side}_elbow_servo"/>
            <origin xyz="0 0 -0.019" rpy="0 -${pi/2} -${pi/2}"/>
            <limit lower="${-pi/2}" upper="${pi/2}" effort="${effort}" velocity="${velocity}"/>
        </joint>
        <xacro:insert_transmission name="${short_side}_elb_y"/>

        <link name="${side}_elbow_servo">
            <visual>
                <origin rpy="0 0 0" xyz="0 0 0"/>
                <geometry>
                    <mesh filename="package://mh5_description/meshes/XL430_no_idle_revC.stl"/>
                </geometry>
                <xacro:material_black/>
            </visual>
            <collision>
                <origin rpy="0 0 0" xyz="0 0 0"/>
                <geometry>
                    <mesh filename="package://mh5_description/meshes/XL430_no_idle_revC.stl"/>
                </geometry>
            </collision>
            <inertial>
                <mass value="0.057"/>
                <inertia
                    ixx="0.000013720"
                    iyy="0.000015234"
                    izz="0.000008769"
                    ixy="0.000000007"
                    ixz="-0.000000355"
                    iyz="0.000000006" />
            </inertial>
        </link>

        <joint name="${side}_lower_arm_fixed" type="fixed">
            <parent link="${side}_elbow_servo"/>
            <child link="${side}_lower_arm_frame"/>
            <origin xyz="0 0 0" rpy="0 0 0"/>
        </joint>

        <link name="${side}_lower_arm_frame">
            <visual>
                <origin rpy="0 0 0" xyz="0 0 -0.03925"/>
                <geometry>
                    <mesh filename="package://mh5_description/meshes/lower_arm.stl"/>
                </geometry>
                <material name="ivory"/>
            </visual>
            <collision>
                <origin rpy="0 0 0" xyz="0 0 -0.03925"/>
                <geometry>
                    <mesh filename="package://mh5_description/meshes/lower_arm.stl"/>
                </geometry>
            </collision>
            <inertial>
                <mass value="0.0011"/>
                <inertia
                    ixx="0.000003873"
                    iyy="0.000002140"
                    izz="0.000003349"
                    ixy="0.000000000"
                    ixz="0.000000004"
                    iyz="0.000000000" />
            </inertial>
        </link>

        <joint name="${short_side}_elb_p" type="revolute">
            <axis xyz="${factor} 0 0"/>
            <parent link="${side}_lower_arm_frame"/>
            <child link="${side}_lower_arm_servo"/>
            <origin xyz="0 0 -0.07325" rpy="0 0 ${-factor*pi/2}"/>
            <limit lower="${-0.6*pi}" upper="${0.6*pi}" effort="${effort}" velocity="${velocity}"/>
        </joint>
        <xacro:insert_transmission name="${short_side}_elb_p"/>

        <link name="${side}_lower_arm_servo">
            <visual>
                <origin rpy="0 0 0" xyz="0 0 0"/>
                <geometry>
                    <mesh filename="package://mh5_description/meshes/XL430_idle_revC.stl"/>
                </geometry>
                <material name="black"/>
            </visual>
            <collision>
                <origin rpy="0 0 0" xyz="0 0 0"/>
                <geometry>
                    <mesh filename="package://mh5_description/meshes/XL430_idle_revC.stl"/>
                </geometry>
            </collision>
            <inertial>
                <mass value="0.057"/>
                <inertia
                    ixx="0.000013720"
                    iyy="0.000015234"
                    izz="0.000008769"
                    ixy="0.000000007"
                    ixz="-0.000000355"
                    iyz="0.000000006" />
            </inertial>
        </link>

        <joint name="${side}_hand_fixed" type="fixed">
            <parent link="${side}_lower_arm_servo"/>
            <child link="${side}_hand"/>
            <origin xyz="0 0 -0.03925" rpy="0 0 ${factor*pi/2}"/>
            <!-- <origin xyz="0 0 -0.03925" rpy="0 0 ${pi/2+factor*pi/2}"/> -->
        </joint>

        <xacro:if value="${short_side == 'l'}">
            <xacro:property name="hand_stl" value = "package://mh5_description/meshes/left_hand_revB.stl"/>
        </xacro:if>
        <xacro:if value="${short_side == 'r'}">
            <xacro:property name="hand_stl" value = "package://mh5_description/meshes/right_hand_revB.stl"/>
        </xacro:if>

        <link name="${side}_hand">
            <visual>
                <origin rpy="0 0 0" xyz="0 0 0"/>
                <geometry>
                    <mesh filename="${hand_stl}"/>
                </geometry>
                <material name="ivory"/>
            </visual>
            <collision>
                <origin rpy="0 0 0" xyz="0 0 0"/>
                <geometry>
                    <mesh filename="${hand_stl}"/>
                </geometry>
            </collision>
            <inertial>
                <mass value="0.0096"/>
                <inertia
                    ixx="0.000002177"
                    iyy="0.000002288"
                    izz="0.000000936"
                    ixy="${factor*0.000000053}"
                    ixz="0.000000020"
                    iyz="${factor*-0.000000052}" />
            </inertial>
        </link>

    </xacro:macro>

</robot>
