<?xml version="1.0" ?>
<robot xmlns:xacro="http://ros.org/wiki/xacro">

    <xacro:macro name="mh5_head" params="parent">

        <link name="head_servo">
            <visual>
                <origin rpy="0 ${pi/2} ${pi/2}" xyz="-0.012 0 0"/>
                <geometry>
                    <mesh filename="package://mh5_description/meshes/2xl430_1_idle.stl"/>
                </geometry>
                <xacro:material_black/>
            </visual>
        </link>

        <joint name="head_y" type="revolute">
            <axis xyz="0 0 1"/>
            <parent link="${parent}"/>
            <child link="head_servo"/>
            <origin xyz="-0.004075 0 0.183" rpy="0 0 0"/>
            <limit lower="-3.1416" upper="3.1416" effort="1000" velocity="100"/>
        </joint>

        <link name="head_frame">
            <visual>
                <origin rpy="0 0 ${pi/2}" xyz="0 0 0"/>
                <geometry>
                    <mesh filename="package://mh5_description/meshes/head.stl"/>
                </geometry>
                <xacro:material_ivory/>
            </visual>
        </link>

        <joint name="head_p" type="revolute">
            <axis xyz="0 -1 0"/>
            <parent link="head_servo"/>
            <child link="head_frame"/>
            <origin xyz="-0.024 0 0" rpy="0 0 0"/>
            <limit lower="-3.1416" upper="3.1416" effort="1000" velocity="100"/>
        </joint>

        <link name="left_camera">
            <visual>
                <origin rpy="0 0 ${pi/2}" xyz="0 0 0"/>
                <geometry>
                    <mesh filename="package://mh5_description/meshes/camera.stl"/>
                </geometry>
                <xacro:material_black/>
            </visual>
        </link>

        <joint name="left_camera_fixed" type="fixed">
            <parent link="head_frame"/>
            <child link="left_camera"/>
            <origin xyz="0.06435 0.018 -0.009347" rpy="0 0 0"/>
        </joint>

        <link name="right_camera">
            <visual>
                <origin rpy="0 0 ${pi/2}" xyz="0 0 0"/>
                <geometry>
                    <mesh filename="package://mh5_description/meshes/camera.stl"/>
                </geometry>
                <xacro:material_black/>
            </visual>
        </link>

        <joint name="right_camera_fixed" type="fixed">
            <parent link="head_frame"/>
            <child link="right_camera"/>
            <origin xyz="0.06435 -0.018 -0.009347" rpy="0 0 0"/>
        </joint>

    </xacro:macro>

</robot>